[2025-03-10T15:22:27.859+0000] {local_task_job_runner.py:123} INFO - ::group::Pre task execution logs
[2025-03-10T15:22:28.209+0000] {taskinstance.py:2614} INFO - Dependencies all met for dep_context=non-requeueable deps ti=<TaskInstance: a1.insert_data_to_mysql manual__2025-03-10T15:18:17.009748+00:00 [queued]>
[2025-03-10T15:22:28.283+0000] {taskinstance.py:2614} INFO - Dependencies all met for dep_context=requeueable deps ti=<TaskInstance: a1.insert_data_to_mysql manual__2025-03-10T15:18:17.009748+00:00 [queued]>
[2025-03-10T15:22:28.290+0000] {taskinstance.py:2867} INFO - Starting attempt 2 of 4
[2025-03-10T15:22:28.526+0000] {taskinstance.py:2890} INFO - Executing <Task(_PythonDecoratedOperator): insert_data_to_mysql> on 2025-03-10 15:18:17.009748+00:00
[2025-03-10T15:22:28.806+0000] {warnings.py:112} WARNING - /home/***/.local/lib/python3.12/site-packages/***/task/task_runner/standard_task_runner.py:70: DeprecationWarning: This process (pid=811) is multi-threaded, use of fork() may lead to deadlocks in the child.
  pid = os.fork()

[2025-03-10T15:22:28.856+0000] {standard_task_runner.py:104} INFO - Running: ['***', 'tasks', 'run', 'a1', 'insert_data_to_mysql', 'manual__2025-03-10T15:18:17.009748+00:00', '--job-id', '66', '--raw', '--subdir', 'DAGS_FOLDER/pipeline.py', '--cfg-path', '/tmp/tmppa4khgun']
[2025-03-10T15:22:28.870+0000] {standard_task_runner.py:105} INFO - Job 66: Subtask insert_data_to_mysql
[2025-03-10T15:22:28.867+0000] {standard_task_runner.py:72} INFO - Started process 826 to run task
[2025-03-10T15:22:29.910+0000] {task_command.py:467} INFO - Running <TaskInstance: a1.insert_data_to_mysql manual__2025-03-10T15:18:17.009748+00:00 [running]> on host 29fec35ab0e4
[2025-03-10T15:22:35.488+0000] {taskinstance.py:3134} INFO - Exporting env vars: AIRFLOW_CTX_DAG_EMAIL='example@gmail.com' AIRFLOW_CTX_DAG_OWNER='***' AIRFLOW_CTX_DAG_ID='a1' AIRFLOW_CTX_TASK_ID='insert_data_to_mysql' AIRFLOW_CTX_EXECUTION_DATE='2025-03-10T15:18:17.009748+00:00' AIRFLOW_CTX_TRY_NUMBER='2' AIRFLOW_CTX_DAG_RUN_ID='manual__2025-03-10T15:18:17.009748+00:00'
[2025-03-10T15:22:35.945+0000] {logging_mixin.py:190} INFO - Task instance is in running state
[2025-03-10T15:22:35.952+0000] {logging_mixin.py:190} INFO -  Previous state of the Task instance: queued
[2025-03-10T15:22:36.004+0000] {logging_mixin.py:190} INFO - Current task name:insert_data_to_mysql state:running start_date:2025-03-10 15:22:28.214069+00:00
[2025-03-10T15:22:36.005+0000] {logging_mixin.py:190} INFO - Dag name:a1 and current dag run status:running
[2025-03-10T15:22:36.012+0000] {taskinstance.py:732} INFO - ::endgroup::
[2025-03-10T15:22:36.119+0000] {logging_mixin.py:190} INFO - attampting to insert data to mysql....
[2025-03-10T15:22:54.514+0000] {base.py:84} INFO - Retrieving connection 'mysql_default'
[2025-03-10T15:23:13.828+0000] {job.py:229} INFO - Heartbeat recovered after 10.79 seconds
[2025-03-10T15:23:30.725+0000] {job.py:229} INFO - Heartbeat recovered after 18.61 seconds
[2025-03-10T15:24:16.567+0000] {job.py:229} INFO - Heartbeat recovered after 17.12 seconds
[2025-03-10T15:24:16.407+0000] {taskinstance.py:3313} ERROR - Task failed with exception
Traceback (most recent call last):
  File "/home/airflow/.local/lib/python3.12/site-packages/airflow/models/taskinstance.py", line 768, in _execute_task
    result = _execute_callable(context=context, **execute_callable_kwargs)
             ^^^^^^^^^^^^^^^^^^^^^^^^^^^^^^^^^^^^^^^^^^^^^^^^^^^^^^^^^^^^^
  File "/home/airflow/.local/lib/python3.12/site-packages/airflow/models/taskinstance.py", line 734, in _execute_callable
    return ExecutionCallableRunner(
           ^^^^^^^^^^^^^^^^^^^^^^^^
  File "/home/airflow/.local/lib/python3.12/site-packages/airflow/utils/operator_helpers.py", line 252, in run
    return self.func(*args, **kwargs)
           ^^^^^^^^^^^^^^^^^^^^^^^^^^
  File "/home/airflow/.local/lib/python3.12/site-packages/airflow/models/baseoperator.py", line 424, in wrapper
    return func(self, *args, **kwargs)
           ^^^^^^^^^^^^^^^^^^^^^^^^^^^
  File "/home/airflow/.local/lib/python3.12/site-packages/airflow/decorators/base.py", line 266, in execute
    return_value = super().execute(context)
                   ^^^^^^^^^^^^^^^^^^^^^^^^
  File "/home/airflow/.local/lib/python3.12/site-packages/airflow/models/baseoperator.py", line 424, in wrapper
    return func(self, *args, **kwargs)
           ^^^^^^^^^^^^^^^^^^^^^^^^^^^
  File "/home/airflow/.local/lib/python3.12/site-packages/airflow/operators/python.py", line 238, in execute
    return_value = self.execute_callable()
                   ^^^^^^^^^^^^^^^^^^^^^^^
  File "/home/airflow/.local/lib/python3.12/site-packages/airflow/operators/python.py", line 256, in execute_callable
    return runner.run(*self.op_args, **self.op_kwargs)
           ^^^^^^^^^^^^^^^^^^^^^^^^^^^^^^^^^^^^^^^^^^^
  File "/home/airflow/.local/lib/python3.12/site-packages/airflow/utils/operator_helpers.py", line 252, in run
    return self.func(*args, **kwargs)
           ^^^^^^^^^^^^^^^^^^^^^^^^^^
  File "/opt/airflow/dags/pipeline.py", line 83, in insert_data_to_mysql
    mysql_hook.run(insert_query)
  File "/home/airflow/.local/lib/python3.12/site-packages/airflow/providers/common/sql/hooks/sql.py", line 463, in run
    with self._create_autocommit_connection(autocommit) as conn:
         ^^^^^^^^^^^^^^^^^^^^^^^^^^^^^^^^^^^^^^^^^^^^^^
  File "/usr/local/lib/python3.12/contextlib.py", line 137, in __enter__
    return next(self.gen)
           ^^^^^^^^^^^^^^
  File "/home/airflow/.local/lib/python3.12/site-packages/airflow/providers/common/sql/hooks/sql.py", line 576, in _create_autocommit_connection
    with closing(self.get_conn()) as conn:
                 ^^^^^^^^^^^^^^^
  File "/home/airflow/.local/lib/python3.12/site-packages/airflow/providers/mysql/hooks/mysql.py", line 224, in get_conn
    return MySQLdb.connect(**conn_config)
           ^^^^^^^^^^^^^^^^^^^^^^^^^^^^^^
  File "/home/airflow/.local/lib/python3.12/site-packages/MySQLdb/__init__.py", line 121, in Connect
    return Connection(*args, **kwargs)
           ^^^^^^^^^^^^^^^^^^^^^^^^^^^
  File "/home/airflow/.local/lib/python3.12/site-packages/MySQLdb/connections.py", line 200, in __init__
    super().__init__(*args, **kwargs2)
MySQLdb.OperationalError: (2002, "Can't connect to server on '34.143.163.187' (115)")
[2025-03-10T15:24:20.578+0000] {logging_mixin.py:190} INFO - Task instance in failure state
[2025-03-10T15:24:21.386+0000] {logging_mixin.py:190} INFO - Task start:2025-03-10 15:22:28.214069+00:00 end:2025-03-10 15:24:20.382943+00:00 duration:112.168874
[2025-03-10T15:24:21.679+0000] {logging_mixin.py:190} INFO - Task:<Task(_PythonDecoratedOperator): insert_data_to_mysql> dag:<DAG: a1> dagrun:<DagRun a1 @ 2025-03-10 15:18:17.009748+00:00: manual__2025-03-10T15:18:17.009748+00:00, state:running, queued_at: 2025-03-10 15:18:17.279474+00:00. externally triggered: True>
[2025-03-10T15:24:21.727+0000] {logging_mixin.py:190} INFO - Failure caused by (2002, "Can't connect to server on '34.143.163.187' (115)")
[2025-03-10T15:24:21.803+0000] {taskinstance.py:1226} INFO - Marking task as UP_FOR_RETRY. dag_id=a1, task_id=insert_data_to_mysql, run_id=manual__2025-03-10T15:18:17.009748+00:00, execution_date=20250310T151817, start_date=20250310T152228, end_date=20250310T152420
[2025-03-10T15:24:29.145+0000] {job.py:229} INFO - Heartbeat recovered after 13.06 seconds
[2025-03-10T15:24:36.470+0000] {taskinstance.py:341} INFO - ::group::Post task execution logs
[2025-03-10T15:24:37.002+0000] {standard_task_runner.py:124} ERROR - Failed to execute job 66 for task insert_data_to_mysql ((2002, "Can't connect to server on '34.143.163.187' (115)"); 826)
Traceback (most recent call last):
  File "/home/airflow/.local/lib/python3.12/site-packages/airflow/task/task_runner/standard_task_runner.py", line 117, in _start_by_fork
    ret = args.func(args, dag=self.dag)
          ^^^^^^^^^^^^^^^^^^^^^^^^^^^^^
  File "/home/airflow/.local/lib/python3.12/site-packages/airflow/cli/cli_config.py", line 49, in command
    return func(*args, **kwargs)
           ^^^^^^^^^^^^^^^^^^^^^
  File "/home/airflow/.local/lib/python3.12/site-packages/airflow/utils/cli.py", line 116, in wrapper
    return f(*args, **kwargs)
           ^^^^^^^^^^^^^^^^^^
  File "/home/airflow/.local/lib/python3.12/site-packages/airflow/cli/commands/task_command.py", line 483, in task_run
    task_return_code = _run_task_by_selected_method(args, _dag, ti)
                       ^^^^^^^^^^^^^^^^^^^^^^^^^^^^^^^^^^^^^^^^^^^^
  File "/home/airflow/.local/lib/python3.12/site-packages/airflow/cli/commands/task_command.py", line 256, in _run_task_by_selected_method
    return _run_raw_task(args, ti)
           ^^^^^^^^^^^^^^^^^^^^^^^
  File "/home/airflow/.local/lib/python3.12/site-packages/airflow/cli/commands/task_command.py", line 341, in _run_raw_task
    return ti._run_raw_task(
           ^^^^^^^^^^^^^^^^^
  File "/home/airflow/.local/lib/python3.12/site-packages/airflow/utils/session.py", line 97, in wrapper
    return func(*args, session=session, **kwargs)
           ^^^^^^^^^^^^^^^^^^^^^^^^^^^^^^^^^^^^^^
  File "/home/airflow/.local/lib/python3.12/site-packages/airflow/models/taskinstance.py", line 3006, in _run_raw_task
    return _run_raw_task(
           ^^^^^^^^^^^^^^
  File "/home/airflow/.local/lib/python3.12/site-packages/airflow/models/taskinstance.py", line 274, in _run_raw_task
    TaskInstance._execute_task_with_callbacks(
  File "/home/airflow/.local/lib/python3.12/site-packages/airflow/models/taskinstance.py", line 3161, in _execute_task_with_callbacks
    result = self._execute_task(context, task_orig)
             ^^^^^^^^^^^^^^^^^^^^^^^^^^^^^^^^^^^^^^
  File "/home/airflow/.local/lib/python3.12/site-packages/airflow/models/taskinstance.py", line 3185, in _execute_task
    return _execute_task(self, context, task_orig)
           ^^^^^^^^^^^^^^^^^^^^^^^^^^^^^^^^^^^^^^^
  File "/home/airflow/.local/lib/python3.12/site-packages/airflow/models/taskinstance.py", line 768, in _execute_task
    result = _execute_callable(context=context, **execute_callable_kwargs)
             ^^^^^^^^^^^^^^^^^^^^^^^^^^^^^^^^^^^^^^^^^^^^^^^^^^^^^^^^^^^^^
  File "/home/airflow/.local/lib/python3.12/site-packages/airflow/models/taskinstance.py", line 734, in _execute_callable
    return ExecutionCallableRunner(
           ^^^^^^^^^^^^^^^^^^^^^^^^
  File "/home/airflow/.local/lib/python3.12/site-packages/airflow/utils/operator_helpers.py", line 252, in run
    return self.func(*args, **kwargs)
           ^^^^^^^^^^^^^^^^^^^^^^^^^^
  File "/home/airflow/.local/lib/python3.12/site-packages/airflow/models/baseoperator.py", line 424, in wrapper
    return func(self, *args, **kwargs)
           ^^^^^^^^^^^^^^^^^^^^^^^^^^^
  File "/home/airflow/.local/lib/python3.12/site-packages/airflow/decorators/base.py", line 266, in execute
    return_value = super().execute(context)
                   ^^^^^^^^^^^^^^^^^^^^^^^^
  File "/home/airflow/.local/lib/python3.12/site-packages/airflow/models/baseoperator.py", line 424, in wrapper
    return func(self, *args, **kwargs)
           ^^^^^^^^^^^^^^^^^^^^^^^^^^^
  File "/home/airflow/.local/lib/python3.12/site-packages/airflow/operators/python.py", line 238, in execute
    return_value = self.execute_callable()
                   ^^^^^^^^^^^^^^^^^^^^^^^
  File "/home/airflow/.local/lib/python3.12/site-packages/airflow/operators/python.py", line 256, in execute_callable
    return runner.run(*self.op_args, **self.op_kwargs)
           ^^^^^^^^^^^^^^^^^^^^^^^^^^^^^^^^^^^^^^^^^^^
  File "/home/airflow/.local/lib/python3.12/site-packages/airflow/utils/operator_helpers.py", line 252, in run
    return self.func(*args, **kwargs)
           ^^^^^^^^^^^^^^^^^^^^^^^^^^
  File "/opt/airflow/dags/pipeline.py", line 83, in insert_data_to_mysql
    mysql_hook.run(insert_query)
  File "/home/airflow/.local/lib/python3.12/site-packages/airflow/providers/common/sql/hooks/sql.py", line 463, in run
    with self._create_autocommit_connection(autocommit) as conn:
         ^^^^^^^^^^^^^^^^^^^^^^^^^^^^^^^^^^^^^^^^^^^^^^
  File "/usr/local/lib/python3.12/contextlib.py", line 137, in __enter__
    return next(self.gen)
           ^^^^^^^^^^^^^^
  File "/home/airflow/.local/lib/python3.12/site-packages/airflow/providers/common/sql/hooks/sql.py", line 576, in _create_autocommit_connection
    with closing(self.get_conn()) as conn:
                 ^^^^^^^^^^^^^^^
  File "/home/airflow/.local/lib/python3.12/site-packages/airflow/providers/mysql/hooks/mysql.py", line 224, in get_conn
    return MySQLdb.connect(**conn_config)
           ^^^^^^^^^^^^^^^^^^^^^^^^^^^^^^
  File "/home/airflow/.local/lib/python3.12/site-packages/MySQLdb/__init__.py", line 121, in Connect
    return Connection(*args, **kwargs)
           ^^^^^^^^^^^^^^^^^^^^^^^^^^^
  File "/home/airflow/.local/lib/python3.12/site-packages/MySQLdb/connections.py", line 200, in __init__
    super().__init__(*args, **kwargs2)
MySQLdb.OperationalError: (2002, "Can't connect to server on '34.143.163.187' (115)")
[2025-03-10T15:24:41.725+0000] {job.py:229} INFO - Heartbeat recovered after 12.98 seconds
[2025-03-10T15:24:44.794+0000] {local_task_job_runner.py:266} INFO - Task exited with return code 1
[2025-03-10T15:24:47.695+0000] {standard_task_runner.py:217} INFO - Process not found (most likely exited), stop collecting metrics
[2025-03-10T15:24:48.127+0000] {taskinstance.py:3901} INFO - 0 downstream tasks scheduled from follow-on schedule check
[2025-03-10T15:24:48.220+0000] {local_task_job_runner.py:245} INFO - ::endgroup::
