[2025-03-09T18:58:08.329+0000] {local_task_job_runner.py:123} INFO - ::group::Pre task execution logs
[2025-03-09T18:58:08.347+0000] {taskinstance.py:2614} INFO - Dependencies all met for dep_context=non-requeueable deps ti=<TaskInstance: a1.insert_data_to_mongodb scheduled__2025-03-08T00:00:00+00:00 [queued]>
[2025-03-09T18:58:08.351+0000] {taskinstance.py:2614} INFO - Dependencies all met for dep_context=requeueable deps ti=<TaskInstance: a1.insert_data_to_mongodb scheduled__2025-03-08T00:00:00+00:00 [queued]>
[2025-03-09T18:58:08.351+0000] {taskinstance.py:2867} INFO - Starting attempt 16 of 19
[2025-03-09T18:58:08.358+0000] {taskinstance.py:2890} INFO - Executing <Task(_PythonDecoratedOperator): insert_data_to_mongodb> on 2025-03-08 00:00:00+00:00
[2025-03-09T18:58:08.371+0000] {warnings.py:112} WARNING - /home/***/.local/lib/python3.12/site-packages/***/task/task_runner/standard_task_runner.py:70: DeprecationWarning: This process (pid=606) is multi-threaded, use of fork() may lead to deadlocks in the child.
  pid = os.fork()

[2025-03-09T18:58:08.373+0000] {standard_task_runner.py:72} INFO - Started process 607 to run task
[2025-03-09T18:58:08.373+0000] {standard_task_runner.py:104} INFO - Running: ['***', 'tasks', 'run', 'a1', 'insert_data_to_mongodb', 'scheduled__2025-03-08T00:00:00+00:00', '--job-id', '33', '--raw', '--subdir', 'DAGS_FOLDER/pipeline.py', '--cfg-path', '/tmp/tmph65i24y6']
[2025-03-09T18:58:08.375+0000] {standard_task_runner.py:105} INFO - Job 33: Subtask insert_data_to_mongodb
[2025-03-09T18:58:08.415+0000] {task_command.py:467} INFO - Running <TaskInstance: a1.insert_data_to_mongodb scheduled__2025-03-08T00:00:00+00:00 [running]> on host a4ea25182d86
[2025-03-09T18:58:08.853+0000] {taskinstance.py:3134} INFO - Exporting env vars: AIRFLOW_CTX_DAG_EMAIL='example@gmail.com' AIRFLOW_CTX_DAG_OWNER='***' AIRFLOW_CTX_DAG_ID='a1' AIRFLOW_CTX_TASK_ID='insert_data_to_mongodb' AIRFLOW_CTX_EXECUTION_DATE='2025-03-08T00:00:00+00:00' AIRFLOW_CTX_TRY_NUMBER='16' AIRFLOW_CTX_DAG_RUN_ID='scheduled__2025-03-08T00:00:00+00:00'
[2025-03-09T18:58:08.855+0000] {logging_mixin.py:190} INFO - Task instance is in running state
[2025-03-09T18:58:08.855+0000] {logging_mixin.py:190} INFO -  Previous state of the Task instance: queued
[2025-03-09T18:58:08.856+0000] {logging_mixin.py:190} INFO - Current task name:insert_data_to_mongodb state:running start_date:2025-03-09 18:58:08.347343+00:00
[2025-03-09T18:58:08.856+0000] {logging_mixin.py:190} INFO - Dag name:a1 and current dag run status:running
[2025-03-09T18:58:08.856+0000] {taskinstance.py:732} INFO - ::endgroup::
[2025-03-09T18:58:08.857+0000] {logging_mixin.py:190} INFO - attampting to insert data to MongoDB....
[2025-03-09T18:58:08.863+0000] {base.py:84} INFO - Retrieving connection 'mongo_default'
[2025-03-09T18:58:12.118+0000] {taskinstance.py:3313} ERROR - Task failed with exception
Traceback (most recent call last):
  File "/home/airflow/.local/lib/python3.12/site-packages/airflow/models/taskinstance.py", line 768, in _execute_task
    result = _execute_callable(context=context, **execute_callable_kwargs)
             ^^^^^^^^^^^^^^^^^^^^^^^^^^^^^^^^^^^^^^^^^^^^^^^^^^^^^^^^^^^^^
  File "/home/airflow/.local/lib/python3.12/site-packages/airflow/models/taskinstance.py", line 734, in _execute_callable
    return ExecutionCallableRunner(
           ^^^^^^^^^^^^^^^^^^^^^^^^
  File "/home/airflow/.local/lib/python3.12/site-packages/airflow/utils/operator_helpers.py", line 252, in run
    return self.func(*args, **kwargs)
           ^^^^^^^^^^^^^^^^^^^^^^^^^^
  File "/home/airflow/.local/lib/python3.12/site-packages/airflow/models/baseoperator.py", line 424, in wrapper
    return func(self, *args, **kwargs)
           ^^^^^^^^^^^^^^^^^^^^^^^^^^^
  File "/home/airflow/.local/lib/python3.12/site-packages/airflow/decorators/base.py", line 266, in execute
    return_value = super().execute(context)
                   ^^^^^^^^^^^^^^^^^^^^^^^^
  File "/home/airflow/.local/lib/python3.12/site-packages/airflow/models/baseoperator.py", line 424, in wrapper
    return func(self, *args, **kwargs)
           ^^^^^^^^^^^^^^^^^^^^^^^^^^^
  File "/home/airflow/.local/lib/python3.12/site-packages/airflow/operators/python.py", line 238, in execute
    return_value = self.execute_callable()
                   ^^^^^^^^^^^^^^^^^^^^^^^
  File "/home/airflow/.local/lib/python3.12/site-packages/airflow/operators/python.py", line 256, in execute_callable
    return runner.run(*self.op_args, **self.op_kwargs)
           ^^^^^^^^^^^^^^^^^^^^^^^^^^^^^^^^^^^^^^^^^^^
  File "/home/airflow/.local/lib/python3.12/site-packages/airflow/utils/operator_helpers.py", line 252, in run
    return self.func(*args, **kwargs)
           ^^^^^^^^^^^^^^^^^^^^^^^^^^
  File "/opt/airflow/dags/pipeline.py", line 36, in insert_data_to_mongodb
    client = mongo_hook.get_conn()
             ^^^^^^^^^^^^^^^^^^^^^
  File "/home/airflow/.local/lib/python3.12/site-packages/airflow/providers/mongo/hooks/mongo.py", line 193, in get_conn
    self.client = MongoClient(self.uri, **options)
                  ^^^^^^^^^^^^^^^^^^^^^^^^^^^^^^^^
  File "/home/airflow/.local/lib/python3.12/site-packages/pymongo/synchronous/mongo_client.py", line 837, in __init__
    opts = _handle_security_options(opts)
           ^^^^^^^^^^^^^^^^^^^^^^^^^^^^^^
  File "/home/airflow/.local/lib/python3.12/site-packages/pymongo/uri_parser.py", line 251, in _handle_security_options
    raise InvalidURI(err_msg % (options.cased_key("ssl"), options.cased_key("tls")))
pymongo.errors.InvalidURI: Can not specify conflicting values for URI options ssl and tls.
[2025-03-09T18:58:12.157+0000] {logging_mixin.py:190} INFO - Task instance in failure state
[2025-03-09T18:58:12.157+0000] {logging_mixin.py:190} INFO - Task start:2025-03-09 18:58:08.347343+00:00 end:2025-03-09 18:58:12.156201+00:00 duration:3.808858
[2025-03-09T18:58:12.158+0000] {logging_mixin.py:190} INFO - Task:<Task(_PythonDecoratedOperator): insert_data_to_mongodb> dag:<DAG: a1> dagrun:<DagRun a1 @ 2025-03-08 00:00:00+00:00: scheduled__2025-03-08T00:00:00+00:00, state:running, queued_at: 2025-03-09 18:58:04.272550+00:00. externally triggered: False>
[2025-03-09T18:58:12.158+0000] {logging_mixin.py:190} INFO - Failure caused by Can not specify conflicting values for URI options ssl and tls.
[2025-03-09T18:58:12.158+0000] {taskinstance.py:1226} INFO - Marking task as UP_FOR_RETRY. dag_id=a1, task_id=insert_data_to_mongodb, run_id=scheduled__2025-03-08T00:00:00+00:00, execution_date=20250308T000000, start_date=20250309T185808, end_date=20250309T185812
[2025-03-09T18:58:12.193+0000] {taskinstance.py:341} INFO - ::group::Post task execution logs
[2025-03-09T18:58:12.195+0000] {standard_task_runner.py:124} ERROR - Failed to execute job 33 for task insert_data_to_mongodb (Can not specify conflicting values for URI options ssl and tls.; 607)
Traceback (most recent call last):
  File "/home/airflow/.local/lib/python3.12/site-packages/airflow/task/task_runner/standard_task_runner.py", line 117, in _start_by_fork
    ret = args.func(args, dag=self.dag)
          ^^^^^^^^^^^^^^^^^^^^^^^^^^^^^
  File "/home/airflow/.local/lib/python3.12/site-packages/airflow/cli/cli_config.py", line 49, in command
    return func(*args, **kwargs)
           ^^^^^^^^^^^^^^^^^^^^^
  File "/home/airflow/.local/lib/python3.12/site-packages/airflow/utils/cli.py", line 116, in wrapper
    return f(*args, **kwargs)
           ^^^^^^^^^^^^^^^^^^
  File "/home/airflow/.local/lib/python3.12/site-packages/airflow/cli/commands/task_command.py", line 483, in task_run
    task_return_code = _run_task_by_selected_method(args, _dag, ti)
                       ^^^^^^^^^^^^^^^^^^^^^^^^^^^^^^^^^^^^^^^^^^^^
  File "/home/airflow/.local/lib/python3.12/site-packages/airflow/cli/commands/task_command.py", line 256, in _run_task_by_selected_method
    return _run_raw_task(args, ti)
           ^^^^^^^^^^^^^^^^^^^^^^^
  File "/home/airflow/.local/lib/python3.12/site-packages/airflow/cli/commands/task_command.py", line 341, in _run_raw_task
    return ti._run_raw_task(
           ^^^^^^^^^^^^^^^^^
  File "/home/airflow/.local/lib/python3.12/site-packages/airflow/utils/session.py", line 97, in wrapper
    return func(*args, session=session, **kwargs)
           ^^^^^^^^^^^^^^^^^^^^^^^^^^^^^^^^^^^^^^
  File "/home/airflow/.local/lib/python3.12/site-packages/airflow/models/taskinstance.py", line 3006, in _run_raw_task
    return _run_raw_task(
           ^^^^^^^^^^^^^^
  File "/home/airflow/.local/lib/python3.12/site-packages/airflow/models/taskinstance.py", line 274, in _run_raw_task
    TaskInstance._execute_task_with_callbacks(
  File "/home/airflow/.local/lib/python3.12/site-packages/airflow/models/taskinstance.py", line 3161, in _execute_task_with_callbacks
    result = self._execute_task(context, task_orig)
             ^^^^^^^^^^^^^^^^^^^^^^^^^^^^^^^^^^^^^^
  File "/home/airflow/.local/lib/python3.12/site-packages/airflow/models/taskinstance.py", line 3185, in _execute_task
    return _execute_task(self, context, task_orig)
           ^^^^^^^^^^^^^^^^^^^^^^^^^^^^^^^^^^^^^^^
  File "/home/airflow/.local/lib/python3.12/site-packages/airflow/models/taskinstance.py", line 768, in _execute_task
    result = _execute_callable(context=context, **execute_callable_kwargs)
             ^^^^^^^^^^^^^^^^^^^^^^^^^^^^^^^^^^^^^^^^^^^^^^^^^^^^^^^^^^^^^
  File "/home/airflow/.local/lib/python3.12/site-packages/airflow/models/taskinstance.py", line 734, in _execute_callable
    return ExecutionCallableRunner(
           ^^^^^^^^^^^^^^^^^^^^^^^^
  File "/home/airflow/.local/lib/python3.12/site-packages/airflow/utils/operator_helpers.py", line 252, in run
    return self.func(*args, **kwargs)
           ^^^^^^^^^^^^^^^^^^^^^^^^^^
  File "/home/airflow/.local/lib/python3.12/site-packages/airflow/models/baseoperator.py", line 424, in wrapper
    return func(self, *args, **kwargs)
           ^^^^^^^^^^^^^^^^^^^^^^^^^^^
  File "/home/airflow/.local/lib/python3.12/site-packages/airflow/decorators/base.py", line 266, in execute
    return_value = super().execute(context)
                   ^^^^^^^^^^^^^^^^^^^^^^^^
  File "/home/airflow/.local/lib/python3.12/site-packages/airflow/models/baseoperator.py", line 424, in wrapper
    return func(self, *args, **kwargs)
           ^^^^^^^^^^^^^^^^^^^^^^^^^^^
  File "/home/airflow/.local/lib/python3.12/site-packages/airflow/operators/python.py", line 238, in execute
    return_value = self.execute_callable()
                   ^^^^^^^^^^^^^^^^^^^^^^^
  File "/home/airflow/.local/lib/python3.12/site-packages/airflow/operators/python.py", line 256, in execute_callable
    return runner.run(*self.op_args, **self.op_kwargs)
           ^^^^^^^^^^^^^^^^^^^^^^^^^^^^^^^^^^^^^^^^^^^
  File "/home/airflow/.local/lib/python3.12/site-packages/airflow/utils/operator_helpers.py", line 252, in run
    return self.func(*args, **kwargs)
           ^^^^^^^^^^^^^^^^^^^^^^^^^^
  File "/opt/airflow/dags/pipeline.py", line 36, in insert_data_to_mongodb
    client = mongo_hook.get_conn()
             ^^^^^^^^^^^^^^^^^^^^^
  File "/home/airflow/.local/lib/python3.12/site-packages/airflow/providers/mongo/hooks/mongo.py", line 193, in get_conn
    self.client = MongoClient(self.uri, **options)
                  ^^^^^^^^^^^^^^^^^^^^^^^^^^^^^^^^
  File "/home/airflow/.local/lib/python3.12/site-packages/pymongo/synchronous/mongo_client.py", line 837, in __init__
    opts = _handle_security_options(opts)
           ^^^^^^^^^^^^^^^^^^^^^^^^^^^^^^
  File "/home/airflow/.local/lib/python3.12/site-packages/pymongo/uri_parser.py", line 251, in _handle_security_options
    raise InvalidURI(err_msg % (options.cased_key("ssl"), options.cased_key("tls")))
pymongo.errors.InvalidURI: Can not specify conflicting values for URI options ssl and tls.
[2025-03-09T18:58:12.238+0000] {local_task_job_runner.py:266} INFO - Task exited with return code 1
[2025-03-09T18:58:12.294+0000] {taskinstance.py:3901} INFO - 0 downstream tasks scheduled from follow-on schedule check
[2025-03-09T18:58:12.295+0000] {local_task_job_runner.py:245} INFO - ::endgroup::
